<?xml version="1.0" encoding="UTF-8" standalone="no"?>
<?pydev-testrun version="1.0"?><pydev-testsuite>
    <summary errors="1" failures="0" finished="true" name="Test Run: 20" tests="0" total_time="Finished in: 0.01 secs."/>
    <test location="C:\Users\Alejandro Molinar\Documents\Programming\PythonP\Beginning\Proof1\ExternalFile2.py" status="error" test="ExternalFile2" time="0">
        <stdout/>
        <stderr>
            <![CDATA[Traceback (most recent call last):
  File "C:\Users\Alejandro Molinar\.p2\pool\plugins\org.python.pydev.core_8.3.0.202104101217\pysrc\_pydev_runfiles\pydev_runfiles.py", line 468, in __get_module_from_str
    mod = __import__(modname)
  File "C:\Users/Alejandro Molinar/Documents/Programming/PythonP/Beginning/Proof1\ExternalFile2.py", line 4, in <module>
    listNames= [Raquel, BellaRaquelita, Andrea, Nataly, Valentina];
NameError: name 'Raquel' is not defined
ERROR: Module: ExternalFile2 could not be imported (file: C:\Users\Alejandro Molinar\Documents\Programming\PythonP\Beginning\Proof1\ExternalFile2.py).
]]>
        </stderr>
    </test>
    <launch mode="run">
        <launch_memento>
            <![CDATA[<?xml version="1.0" encoding="UTF-8" standalone="no"?>
<launchConfiguration local="true" path="Beginning ExternalFile2.py (1)"/>
]]>
        </launch_memento>
    </launch>
</pydev-testsuite>
